Workbook

Sheet Trims
A1: Mmad | B1: Ticker | C1: TypeValeur | D1: 2022_T1 | E1: 2022_T2 | F1: 2022_T3 | G1: 2022_T4 | H1: 2023_T1 | I1: 2023_T2 | J1: 2023_T3 | K1: 2023_T4 | L1: 2024_T1 | M1: 2024_T2 | N1: 2024_T3 | O1: 2024_T4 | P1: 2025_T1 | Q1: 2025_T2 | R1: 2025_T3 | S1: 2025_T4 | T1: 2026_T1 | U1: 2026_T2 | V1: 2026_T3 | W1: 2026_T4
A2: Assurances
A3: ATLANTASANAD | B3: ATL | C3: CA | D3: 1960 | E3: 1122 | F3: 1063 | G3: 1258 | H3: 1893 | I3: 1192 | J3: 906 | K3: 1121 | L3: 1962 | M3: 1134 | N3: 855 | O3: 1309 | P3: 2287 | Q3: 1376 | R3: 876 | S3: 1511 | T3: 2373
A4: WAFA ASSURANCE | B4: WAA | C4: CA | D4: 3117 | E4: 2776 | F4: 2560 | G4: 3185 | H4: 3605 | I4: 2928 | J4: 3119 | K4: 3072 | L4: 4073 | M4: 3027 | N4: 2809 | O4: 3158 | P4: 4352 | Q4: 3530 | R4: 3037 | S4: 4307 | T4: 6400
A5: SANLAM | B5: SAH | C5: CA | D5: 1794 | E5: =3367-Table_Trims[[#This Row],[2022_T1]] -> 1573 | F5: =190+1073 -> 1263 | G5: =1108+217 -> 1325 | H5: =266+1927 -> 2193 | I5: =3493-Table_Trims[[#This Row],[2023_T1]] -> 1300 | J5: =4774-Table_Trims[[#This Row],[2023_T2]]-Table_Trims[[#This Row],[2023_T1]] -> 1281 | K5: 1378 | L5: =1946+201 -> 2147 | M5: =3535-Table_Trims[[#This Row],[2024_T1]] -> 1388 | N5: =1385 -> 1385 | O5: 1361 | P5: =148+1932 -> 2080 | Q5: =3430-Table_Trims[[#This Row],[2025_T1]] -> 1350 | R5: 1429 | S5: 1336 | T5: =268+2009 -> 2277
A6: SALAFIN | B6: SLF | C6: CA | D6: 94.424 | E6: 100.868 | F6: 95.087 | G6: 108.914 | H6: 95.134 | I6: 97.076 | J6: 97.971 | K6: 105.988 | L6: 93.236 | M6: 92.614 | N6: 94.66 | O6: 98.135 | P6: 94 | Q6: 97 | R6: 95 | S6: 98 | T6: 94
A7: Banques
A8: ATTIJARIWAFA BANK | B8: ATW | C8: CA | D8: 6600 | E8: 6500 | F8: 6600 | G8: 6613 | H8: 6861 | I8: 7743 | J8: 7683 | K8: 7656 | L8: 8520 | M8: 8503 | N8: 8150 | O8: 9334 | P8: 9024 | Q8: 8672 | R8: 8658 | S8: 8567 | T8: 9287.857
A9: BANK OF AFRICA | B9: BOA | C9: CA | D9: 3630 | E9: 4070 | F9: 3655 | G9: 4271 | H9: 3834 | I9: 4571 | J9: 4194 | K9: 4343 | L9: 4500 | M9: 5120 | N9: 4480 | O9: 4522 | P9: 4968 | Q9: 5519 | R9: 4792 | S9: 5069 | T9: 4860.039
A10: BCP | B10: BCP | C10: CA | D10: 4902 | E10: 5559 | F10: 4371 | G10: 5777 | H10: 4822 | I10: 6920 | J10: 5910 | K10: 5143 | L10: 6048 | M10: 6790 | N10: 6752 | O10: 6011 | P10: 6949 | Q10: 6963 | R10: 6492 | S10: 6596 | T10: 5724
A11: BMCI | B11: BCI | C11: CA | D11: 759 | E11: 761 | F11: 745 | G11: 790 | H11: 792 | I11: 902 | J11: 876 | K11: 870 | L11: 910 | M11: 980 | N11: 980 | O11: 920 | P11: 983 | Q11: 1007 | R11: 960 | S11: 990 | T11: 961
A12: CDM | B12: CDM | C12: CA | D12: 648 | E12: 637 | F12: 640 | G12: 644.1 | H12: 719 | I12: 707 | J12: 770 | K12: 704 | L12: 791 | M12: 815 | N12: 833 | O12: 861 | P12: 890 | Q12: 885 | R12: 903 | S12: 790 | T12: 928
A13: CFG BANK | B13: CFG | C13: CA | D13: 116 | E13: 113 | F13: 127 | G13: 144 | H13: 144 | I13: 165 | J13: 189 | K13: 159 | L13: 208 | M13: 216 | N13: 254 | O13: 263 | P13: 303 | Q13: 297 | R13: 309 | S13: 338 | T13: 310
A14: CIH | B14: CIH | C14: CA | D14: 812.3 | E14: 812 | F14: 885.4 | G14: 1008.3 | H14: 968.5 | I14: 1250.4 | J14: 1108 | K14: 1141 | L14: 1122.7 | M14: 1210 | N14: 1203.4 | O14: 1202.9 | P14: 1300 | Q14: 1448 | R14: 1292.8 | S14: 1382 | T14: 1269.4
A15: Services Financiers
A16: EQDOM | B16: EQD | C16: CA | D16: 142 | E16: 165 | F16: 134 | G16: 140 | H16: 132 | I16: 161 | J16: 124 | K16: 130 | L16: 130 | M16: 152 | N16: 132 | O16: 129 | P16: 140 | Q16: 166 | R16: 140 | S16: =590-Table_Trims[[#This Row],[2025_T3]]-Table_Trims[[#This Row],[2025_T2]]-Table_Trims[[#This Row],[2025_T1]] -> 144 | T16: 154
A17: SALAFIN | B17: SLF | C17: CA | D17: 94.424 | E17: 100.868 | F17: 95.087 | G17: 108.914 | H17: 95.424 | I17: 97.076 | J17: 97.971 | K17: 105.988 | L17: 93.236 | M17: 92.614 | N17: 94.66 | O17: 98.135 | P17: 94 | Q17: 97 | R17: 95
A18: Cash Plus | B18: CAP | C18: CA | O18: 186 | P18: 212 | S18: 222 | T18: 234
A19: Agroalimentaire et Boissons
A20: COSUMAR | B20: CSR | C20: CA | D20: 2486 | E20: 2590 | F20: 2823 | G20: 2534 | H20: 2512 | I20: 2446 | J20: 2700 | K20: 2575 | L20: 2439 | M20: 2544 | N20: 2766 | O20: 2489 | P20: 2667 | Q20: 2695 | R20: 2675 | S20: 2450 | T20: 2206
A21: COSUMAR | B21: CSR | C21: Capex | D21: 60 | E21: 105 | F21: 56 | G21: 62 | H21: 51 | I21: 53 | J21: 26 | K21: 112 | L21: 54 | M21: 34 | N21: 47 | O21: 65 | P21: 36 | Q21: 56 | R21: 74 | S21: 79 | T21: 25
A22: COSUMAR | B22: CSR | C22: Endettement | D22: -174 | E22: 1011 | F22: 167 | G22: 985 | H22: 694 | I22: 919 | J22: 1796 | K22: 1458 | L22: -137 | M22: 1062 | N22: 1823 | O22: 556 | P22: -27 | Q22: 1608 | R22: 1701 | S22: 206 | T22: 986
A23: LESIEUR CRISTAL | B23: LES | C23: CA | D23: 1644 | E23: 1954 | F23: 1641 | G23: 1650 | H23: 1827 | I23: 1212 | J23: 1510 | K23: 1385 | L23: 1506 | M23: 1205 | N23: 1036 | O23: 1381 | P23: 1656 | Q23: 1168 | R23: 1227 | S23: 1216 | T23: 1447
A24: LESIEUR CRISTAL | B24: LES | C24: Capex | D24: 16 | E24: 41 | F24: 9 | G24: 100 | H24: 11.3 | I24: 22.7 | J24: 37 | K24: 47 | L24: 48 | M24: 52 | N24: 9 | O24: 50 | P24: 6 | Q24: 13 | R24: 9 | S24: 33 | T24: 14
A25: LESIEUR CRISTAL | B25: LES | C25: Endettement | D25: -1002 | E25: -921 | F25: -1087 | G25: -1094 | H25: -1551 | I25: -1094 | J25: -1659 | K25: 36 | L25: -279 | M25: 24 | N25: -168 | O25: 196 | P25: 60 | Q25: 281 | R25: 12 | S25: 243 | T25: 139
A26: MUTANDIS | B26: MUT | C26: CA | D26: 422 | E26: 599 | F26: 708 | G26: 600 | H26: 518 | I26: 582 | J26: 703 | K26: 694 | L26: 470 | M26: 495 | N26: 637 | O26: 514 | P26: 452 | Q26: 450 | R26: 592 | S26: 528 | T26: 423
A27: MUTANDIS | B27: MUT | C27: Capex | D27: 51 | E27: 55 | F27: 60 | G27: 52 | H27: 42 | I27: 59 | J27: 43 | K27: 385 | L27: 72 | M27: 52 | N27: 31 | O27: 106 | P27: 37 | Q27: 26 | R27: -14 | S27: 39 | T27: 37
A28: MUTANDIS | B28: MUT | C28: Endettement | D28: 558 | E28: 586 | F28: 756 | G28: 739 | H28: 875 | I28: 954 | J28: 1262 | K28: 1102 | L28: 1075 | M28: 710 | N28: 869 | O28: 850 | P28: 950 | Q28: 938 | R28: 885 | S28: 828 | T28: 929
A29: SOCIETE DES BOISSONS DU MAROC | B29: SBM | C29: CA | D29: 496 | E29: 602 | F29: 995 | G29: 820 | H29: 466 | I29: 747 | J29: 973 | K29: 745 | L29: 361.5 | M29: 756 | N29: 918 | O29: 826 | P29: 351.3 | Q29: 830 | R29: 971 | S29: 930
A30: SOCIETE DES BOISSONS DU MAROC | B30: SBM | C30: Capex | D30: 5 | E30: 12 | F30: 12 | G30: 39 | H30: 8.7 | I30: 88 | J30: 43 | K30: 55 | L30: 14.9 | M30: 38 | N30: 27 | O30: 34 | P30: 12.7 | Q30: 37 | R30: 31 | S30: 20
A31: SOCIETE DES BOISSONS DU MAROC | B31: SBM | C31: Endettement | D31: -737 | E31: -760 | F31: -511 | G31: -841 | H31: -873.5 | I31: -319 | J31: -834 | K31: -941 | L31: -821 | M31: -365 | N31: -558 | O31: -556 | P31: -389.6 | Q31: -253 | R31: -446 | S31: -593
A32: BTP
A33: JET CONTRACTORS | B33: JET | C33: CA | D33: 342.87 | E33: 527.14 | F33: 284.8 | G33: 559 | H33: 520.66 | I33: 514.06 | J33: 382.89 | K33: 902.1 | L33: 603.32 | M33: 849 | N33: 382.89 | O33: 838.24 | P33: 734.51 | Q33: 788.61 | R33: 854.37 | S33: 1343 | T33: 771.92
A34: JET CONTRACTORS | B34: JET | C34: Capex | D34: 6.07 | E34: 3.96 | F34: 39.26 | G34: 17.77 | H34: 7.33 | I34: 17.94 | J34: 5.64 | K34: 4.6 | L34: 16.77 | M34: 21.64 | N34: 28.38 | O34: 4.1 | P34: 8.61 | Q34: 28.85 | R34: 207.34 | S34: 166 | T34: 50.4
A35: JET CONTRACTORS | B35: JET | C35: Endettement | D35: 1032.86 | E35: 1078.43 | F35: 861.3 | G35: 843.93 | H35: 936.71 | I35: 1169.48 | J35: 1108.62 | K35: 1015.9 | L35: 872.34 | M35: 973.61 | N35: 1108.62 | O35: 1001.67 | P35: 1060.71 | Q35: 1555.69 | R35: 1547.01 | S35: 1640 | T35: 1818.01
A36: LAFARGEHOLCIM MAROC | B36: LHM | C36: CA | D36: 2077 | E36: 1927 | F36: 1898 | G36: 2082 | H36: 2131 | I36: 1999 | J36: 1952 | K36: 2130 | L36: 1884 | M36: 1807 | N36: 2110 | O36: 2354 | P36: 2048 | Q36: 2111 | R36: 2367 | S36: 2354 | T36: 1774
A37: LAFARGEHOLCIM MAROC | B37: LHM | C37: Endettement | D37: 5142 | E37: 6270 | F37: 5998 | G37: 5486 | H37: 4887 | I37: 4600 | J37: 5439 | K37: 4864 | L37: 4622 | M37: 5661 | N37: 4832 | O37: 4034 | P37: 3876 | Q37: 4881 | R37: 4004 | S37: 4034 | T37: 3439
A38: SONASID | B38: SID | C38: CA | D38: 1345 | E38: 1107 | F38: 1196 | G38: 1240 | H38: 1343 | I38: 1200 | J38: 1126 | K38: 1326 | L38: 1249 | M38: 1188 | N38: 1365 | O38: 1692 | P38: 1551 | Q38: 1503 | R38: 1478 | S38: 1854 | T38: 1395
A39: SONASID | B39: SID | C39: Capex | D39: 1 | E39: 21 | F39: 24 | G39: 96 | H39: 15 | I39: 58 | J39: 17 | K39: 129 | L39: 12 | M39: 62 | N39: 32 | O39: 91 | P39: 40 | Q39: 60 | R39: 52 | S39: 125 | T39: 101
A40: SONASID | B40: SID | C40: Endettement | D40: -974 | E40: -816 | F40: -878 | G40: -852 | H40: -928 | I40: -778 | J40: -702 | K40: -768 | L40: -769 | M40: -532 | N40: -656 | O40: -722 | P40: -572 | Q40: -341 | R40: -413 | S40: -400 | T40: -499
...

Sheet Semestriel
A1: Mmad | B1: Ticker | C1: TypeValeur | D1: S1_2022 | E1: S2_2022 | F1: S1_2023 | G1: S2_2023 | H1: S1_2024 | I1: S2_2024 | J1: S1_2025 | K1: S2_2025
A2: Assurances
A3: ATLANTASANAD | B3: ATL | C3: CA | D3: =Trims!D3+Trims!E3 -> 3082 | E3: =Trims!F3+Trims!G3 -> 2321 | F3: =Trims!H3+Trims!I3 -> 3085 | G3: =Trims!J3+Trims!K3 -> 2027 | H3: =Trims!L3+Trims!M3 -> 3096 | I3: =Trims!N3+Trims!O3 -> 2164 | J3: =Trims!P3+Trims!Q3 -> 3663 | K3: =Table_Trims[[#This Row],[2025_T3]]+Table_Trims[[#This Row],[2025_T4]] -> 2387
A4: WAFA ASSURANCE | B4: WAA | C4: CA | D4: =Trims!D4+Trims!E4 -> 5893 | E4: =Trims!F4+Trims!G4 -> 5745 | F4: =Trims!H4+Trims!I4 -> 6533 | G4: =Trims!J4+Trims!K4 -> 6191 | H4: =Trims!L4+Trims!M4 -> 7100 | I4: =Trims!N4+Trims!O4 -> 5967 | J4: =Trims!P4+Trims!Q4 -> 7882 | K4: =Table_Trims[[#This Row],[2025_T3]]+Table_Trims[[#This Row],[2025_T4]] -> 7344
A5: Banques
A6: ATTIJARIWAFA BANK | B6: ATW | C6: CA | D6: =Trims!D8+Trims!E8 -> 13100 | E6: =Trims!F8+Trims!G8 -> 13213 | F6: =Trims!H8+Trims!I8 -> 14604 | G6: =Trims!J8+Trims!K8 -> 15339 | H6: =Trims!L8+Trims!M8 -> 17023 | I6: =Trims!N8+Trims!O8 -> 17484 | J6: =Trims!P8+Trims!Q8 -> 17696 | K6: =Trims!R8+Trims!S8 -> 17225
A7: BANK OF AFRICA | B7: BOA | C7: CA | D7: =Trims!D9+Trims!E9 -> 7700 | E7: =Trims!F9+Trims!G9 -> 7926 | F7: =Trims!H9+Trims!I9 -> 8405 | G7: =Trims!J9+Trims!K9 -> 8537 | H7: =Trims!L9+Trims!M9 -> 9620 | I7: =Trims!N9+Trims!O9 -> 9002 | J7: =Trims!P9+Trims!Q9 -> 10487 | K7: =Trims!R9+Trims!S9 -> 9861
A8: BCP | B8: BCP | C8: CA | D8: =Trims!D10+Trims!E10 -> 10461 | E8: =Trims!F10+Trims!G10 -> 10148 | F8: =Trims!H10+Trims!I10 -> 11742 | G8: =Trims!J10+Trims!K10 -> 11053 | H8: =Trims!L10+Trims!M10 -> 12838 | I8: =Trims!N10+Trims!O10 -> 12763 | J8: =Trims!P10+Trims!Q10 -> 13912 | K8: =Trims!R10+Trims!S10 -> 13088
A9: BMCI | B9: BCI | C9: CA | D9: =Trims!D11+Trims!E11 -> 1520 | E9: =Trims!F11+Trims!G11 -> 1535 | F9: =Trims!H11+Trims!I11 -> 1694 | G9: =Trims!J11+Trims!K11 -> 1746 | H9: =Trims!L11+Trims!M11 -> 1890 | I9: =Trims!N11+Trims!O11 -> 1900 | J9: =Trims!P11+Trims!Q11 -> 1990 | K9: =Trims!R11+Trims!S11 -> 1950
A10: CDM | B10: CDM | C10: CA | D10: =Trims!D12+Trims!E12 -> 1285 | E10: =Trims!F12+Trims!G12 -> 1284.1 | F10: =Trims!H12+Trims!I12 -> 1426 | G10: =Trims!J12+Trims!K12 -> 1474 | H10: =Trims!L12+Trims!M12 -> 1606 | I10: =Trims!N12+Trims!O12 -> 1694 | J10: =Trims!P12+Trims!Q12 -> 1775 | K10: =Trims!R12+Trims!S12 -> 1693
A11: CFG BANK | B11: CFG | C11: CA | D11: =Trims!D13+Trims!E13 -> 229 | E11: =Trims!F13+Trims!G13 -> 271 | F11: =Trims!H13+Trims!I13 -> 309 | G11: =Trims!J13+Trims!K13 -> 348 | H11: =Trims!L13+Trims!M13 -> 424 | I11: =Trims!N13+Trims!O13 -> 517 | J11: =Trims!P13+Trims!Q13 -> 600 | K11: =Trims!R13+Trims!S13 -> 647
A12: CIH | B12: CIH | C12: CA | D12: =Trims!D14+Trims!E14 -> 1624.3 | E12: =Trims!F14+Trims!G14 -> 1893.7 | F12: =Trims!H14+Trims!I14 -> 2218.9 | G12: =Trims!J14+Trims!K14 -> 2249 | H12: =Trims!L14+Trims!M14 -> 2332.7 | I12: =Trims!N14+Trims!O14 -> 2406.3 | J12: =Trims!P14+Trims!Q14 -> 2748 | K12: =Table_Trims[[#This Row],[2025_T3]]+Table_Trims[[#This Row],[2025_T4]] -> 1693
A13: Services Financiers
A14: EQDOM | B14: EQD | C14: CA | D14: =Trims!D16+Trims!E16 -> 307 | E14: =Trims!F16+Trims!G16 -> 274 | F14: =Trims!H16+Trims!I16 -> 293 | G14: =Trims!J16+Trims!K16 -> 254 | H14: =Trims!L16+Trims!M16 -> 282 | I14: =Trims!N16+Trims!O16 -> 261 | J14: =Trims!P16+Trims!Q16 -> 306 | K14: =Table_Trims[[#This Row],[2025_T3]]+Table_Trims[[#This Row],[2025_T4]] -> 2674.8
A15: SALAFIN | B15: SLF | C15: CA | D15: =Trims!D17+Trims!E17 -> 195.292 | E15: =Trims!F17+Trims!G17 -> 204.001 | F15: =Trims!H17+Trims!I17 -> 192.5 | G15: =Trims!J17+Trims!K17 -> 203.959 | H15: =Trims!L17+Trims!M17 -> 185.85 | I15: =Trims!N17+Trims!O17 -> 192.795 | J15: =Trims!P17+Trims!Q17 -> 191 | K15: =Table_Trims[[#This Row],[2025_T3]]+Table_Trims[[#This Row],[2025_T4]] -> 0
A16: Cash Plus | B16: CAP | C16: CA | J16: =Trims!P18+Trims!Q18 -> 212
A17: Agroalimentaire et Boissons
A18: COSUMAR | B18: CSR | C18: CA | D18: =Trims!D20+Trims!E20 -> 5076 | E18: =Trims!F20+Trims!G20 -> 5357 | F18: =Trims!H20+Trims!I20 -> 4958 | G18: =Trims!J20+Trims!K20 -> 5275 | H18: =Trims!L20+Trims!M20 -> 4983 | I18: =Trims!N20+Trims!O20 -> 5255 | J18: =Trims!P20+Trims!Q20 -> 5362 | K18: =Table_Trims[[#This Row],[2025_T3]]+Table_Trims[[#This Row],[2025_T4]] -> 222
A19: COSUMAR | B19: CSR | C19: Capex | D19: =Trims!D21+Trims!E21 -> 165 | E19: =Trims!F21+Trims!G21 -> 118 | F19: =Trims!H21+Trims!I21 -> 104 | G19: =Trims!J21+Trims!K21 -> 138 | H19: =Trims!L21+Trims!M21 -> 88 | I19: =Trims!N21+Trims!O21 -> 112 | J19: =Trims!P21+Trims!Q21 -> 92 | K19: =Table_Trims[[#This Row],[2025_T3]]+Table_Trims[[#This Row],[2025_T4]] -> 0
A20: COSUMAR | B20: CSR | C20: Endettement | D20: =Table_Trims[[#This Row],[2022_T2]] -> 2590 | E20: =Table_Trims[[#This Row],[2022_T4]] -> 2534 | F20: =Table_Trims[[#This Row],[2023_T2]] -> 2446 | G20: =Table_Trims[[#This Row],[2023_T4]] -> 2575 | H20: =Table_Trims[[#This Row],[2024_T2]] -> 2544 | I20: =Table_Trims[[#This Row],[2024_T4]] -> 2489 | J20: =Table_Trims[[#This Row],[2025_T2]] -> 2695 | K20: =Table_Trims[[#This Row],[2025_T4]] -> 2450
A21: LESIEUR CRISTAL | B21: LES | C21: CA | D21: =Trims!D23+Trims!E23 -> 3598 | E21: =Trims!F23+Trims!G23 -> 3291 | F21: =Trims!H23+Trims!I23 -> 3039 | G21: =Trims!J23+Trims!K23 -> 2895 | H21: =Trims!L23+Trims!M23 -> 2711 | I21: =Trims!N23+Trims!O23 -> 2417 | J21: =Trims!P23+Trims!Q23 -> 2824 | K21: =Table_Trims[[#This Row],[2025_T3]]+Table_Trims[[#This Row],[2025_T4]] -> 153
A22: LESIEUR CRISTAL | B22: LES | C22: Capex | D22: =Trims!D24+Trims!E24 -> 57 | E22: =Trims!F24+Trims!G24 -> 109 | F22: =Trims!H24+Trims!I24 -> 34 | G22: =Trims!J24+Trims!K24 -> 84 | H22: =Trims!L24+Trims!M24 -> 100 | I22: =Trims!N24+Trims!O24 -> 59 | J22: =Trims!P24+Trims!Q24 -> 19 | K22: =Table_Trims[[#This Row],[2025_T3]]+Table_Trims[[#This Row],[2025_T4]] -> 1907
A23: LESIEUR CRISTAL | B23: LES | C23: Endettement | D23: =Table_Trims[[#This Row],[2022_T2]] -> 1954 | E23: =Table_Trims[[#This Row],[2022_T4]] -> 1650 | F23: =Table_Trims[[#This Row],[2023_T2]] -> 1212 | G23: =Table_Trims[[#This Row],[2023_T4]] -> 1385 | H23: =Table_Trims[[#This Row],[2024_T2]] -> 1205 | I23: =Table_Trims[[#This Row],[2024_T4]] -> 1381 | J23: =Table_Trims[[#This Row],[2025_T2]] -> 1168 | K23: =Table_Trims[[#This Row],[2025_T4]] -> 1216
A24: MUTANDIS | B24: MUT | C24: CA | D24: =Trims!D26+Trims!E26 -> 1021 | E24: =Trims!F26+Trims!G26 -> 1308 | F24: =Trims!H26+Trims!I26 -> 1100 | G24: =Trims!J26+Trims!K26 -> 1397 | H24: =Trims!L26+Trims!M26 -> 965 | I24: =Trims!N26+Trims!O26 -> 1151 | J24: =Trims!P26+Trims!Q26 -> 902 | K24: =Table_Trims[[#This Row],[2025_T3]]+Table_Trims[[#This Row],[2025_T4]] -> 42
A25: MUTANDIS | B25: MUT | C25: Capex | D25: =Trims!D27+Trims!E27 -> 106 | E25: =Trims!F27+Trims!G27 -> 112 | F25: =Trims!H27+Trims!I27 -> 101 | G25: =Trims!J27+Trims!K27 -> 428 | H25: =Trims!L27+Trims!M27 -> 124 | I25: =Trims!N27+Trims!O27 -> 137 | J25: =Trims!P27+Trims!Q27 -> 63 | K25: =Table_Trims[[#This Row],[2025_T3]]+Table_Trims[[#This Row],[2025_T4]] -> 255
A26: MUTANDIS | B26: MUT | C26: Endettement | D26: =Table_Trims[[#This Row],[2022_T2]] -> 599 | E26: =Table_Trims[[#This Row],[2022_T4]] -> 600 | F26: =Table_Trims[[#This Row],[2023_T2]] -> 582 | G26: =Table_Trims[[#This Row],[2023_T4]] -> 694 | H26: =Table_Trims[[#This Row],[2024_T2]] -> 495 | I26: =Table_Trims[[#This Row],[2024_T4]] -> 514 | J26: =Table_Trims[[#This Row],[2025_T2]] -> 450 | K26: =Table_Trims[[#This Row],[2025_T4]] -> 528
A27: SOCIETE DES BOISSONS DU MAROC | B27: SBM | C27: CA | D27: =Trims!D29+Trims!E29 -> 1098 | E27: =Trims!F29+Trims!G29 -> 1815 | F27: =Trims!H29+Trims!I29 -> 1213 | G27: =Trims!J29+Trims!K29 -> 1718 | H27: =Trims!L29+Trims!M29 -> 1117.5 | I27: =Trims!N29+Trims!O29 -> 1744 | J27: =Trims!P29+Trims!Q29 -> 1181.3 | K27: =Table_Trims[[#This Row],[2025_T3]]+Table_Trims[[#This Row],[2025_T4]] -> 25
A28: SOCIETE DES BOISSONS DU MAROC | B28: SBM | C28: Capex | D28: =Trims!D30+Trims!E30 -> 17 | E28: =Trims!F30+Trims!G30 -> 51 | F28: =Trims!H30+Trims!I30 -> 96.7 | G28: =Trims!J30+Trims!K30 -> 98 | H28: =Trims!L30+Trims!M30 -> 52.9 | I28: =Trims!N30+Trims!O30 -> 61 | J28: =Trims!P30+Trims!Q30 -> 49.7 | K28: =Table_Trims[[#This Row],[2025_T3]]+Table_Trims[[#This Row],[2025_T4]] -> 1713
A29: SOCIETE DES BOISSONS DU MAROC | B29: SBM | C29: Endettement | D29: =Table_Trims[[#This Row],[2022_T2]] -> 602 | E29: =Table_Trims[[#This Row],[2022_T4]] -> 820 | F29: =Table_Trims[[#This Row],[2023_T2]] -> 747 | G29: =Table_Trims[[#This Row],[2023_T4]] -> 745 | H29: =Table_Trims[[#This Row],[2024_T2]] -> 756 | I29: =Table_Trims[[#This Row],[2024_T4]] -> 826 | J29: =Table_Trims[[#This Row],[2025_T2]] -> 830 | K29: =Table_Trims[[#This Row],[2025_T4]] -> 930
A30: BTP
A31: JET CONTRACTORS | B31: JET | C31: CA | D31: =Trims!D33+Trims!E33 -> 870.01 | E31: =Trims!F33+Trims!G33 -> 843.8 | F31: =Trims!H33+Trims!I33 -> 1034.72 | G31: =Trims!J33+Trims!K33 -> 1284.99 | H31: =Trims!L33+Trims!M33 -> 1452.32 | I31: =Trims!N33+Trims!O33 -> 1221.13 | J31: =Trims!P33+Trims!Q33 -> 1523.12 | K31: =Table_Trims[[#This Row],[2025_T3]]+Table_Trims[[#This Row],[2025_T4]] -> -1039
A32: JET CONTRACTORS | B32: JET | C32: Capex | D32: =Trims!D34+Trims!E34 -> 10.03 | E32: =Trims!F34+Trims!G34 -> 57.03 | F32: =Trims!H34+Trims!I34 -> 25.27 | G32: =Trims!J34+Trims!K34 -> 10.24 | H32: =Trims!L34+Trims!M34 -> 38.41 | I32: =Trims!N34+Trims!O34 -> 32.48 | J32: =Trims!P34+Trims!Q34 -> 37.46 | K32: =Table_Trims[[#This Row],[2025_T3]]+Table_Trims[[#This Row],[2025_T4]] -> 0
A33: JET CONTRACTORS | B33: JET | C33: Endettement | D33: =Table_Trims[[#This Row],[2022_T2]] -> 527.14 | E33: =Table_Trims[[#This Row],[2022_T4]] -> 559 | F33: =Table_Trims[[#This Row],[2023_T2]] -> 514.06 | G33: =Table_Trims[[#This Row],[2023_T4]] -> 902.1 | H33: =Table_Trims[[#This Row],[2024_T2]] -> 849 | I33: =Table_Trims[[#This Row],[2024_T4]] -> 838.24 | J33: =Table_Trims[[#This Row],[2025_T2]] -> 788.61 | K33: =Table_Trims[[#This Row],[2025_T4]] -> 1343
A34: LAFARGEHOLCIM MAROC | B34: LHM | C34: CA | D34: =Trims!D36+Trims!E36 -> 4004 | E34: =Trims!F36+Trims!G36 -> 3980 | F34: =Trims!H36+Trims!I36 -> 4130 | G34: =Trims!J36+Trims!K36 -> 4082 | H34: =Trims!L36+Trims!M36 -> 3691 | I34: =Trims!N36+Trims!O36 -> 4464 | J34: =Trims!P36+Trims!Q36 -> 4159 | K34: =Table_Trims[[#This Row],[2025_T3]]+Table_Trims[[#This Row],[2025_T4]] -> 373.34
A35: LAFARGEHOLCIM MAROC | B35: LHM | C35: Endettement | D35: =Table_Trims[[#This Row],[2022_T2]] -> 1078.43 | E35: =Table_Trims[[#This Row],[2022_T4]] -> 843.93 | F35: =Table_Trims[[#This Row],[2023_T2]] -> 1169.48 | G35: =Table_Trims[[#This Row],[2023_T4]] -> 1015.9 | H35: =Table_Trims[[#This Row],[2024_T2]] -> 973.61 | I35: =Table_Trims[[#This Row],[2024_T4]] -> 1001.67 | J35: =Table_Trims[[#This Row],[2025_T2]] -> 1555.69 | K35: =Table_Trims[[#This Row],[2025_T4]] -> 1640
A36: SONASID | B36: SID | C36: CA | D36: =Trims!D38+Trims!E38 -> 2452 | E36: =Trims!F38+Trims!G38 -> 2436 | F36: =Trims!H38+Trims!I38 -> 2543 | G36: =Trims!J38+Trims!K38 -> 2452 | H36: =Trims!L38+Trims!M38 -> 2437 | I36: =Trims!N38+Trims!O38 -> 3057 | J36: =Trims!P38+Trims!Q38 -> 3054 | K36: =Table_Trims[[#This Row],[2025_T3]]+Table_Trims[[#This Row],[2025_T4]] -> 4721
A37: SONASID | B37: SID | C37: Capex | D37: =Trims!D39+Trims!E39 -> 22 | E37: =Trims!F39+Trims!G39 -> 120 | F37: =Trims!H39+Trims!I39 -> 73 | G37: =Trims!J39+Trims!K39 -> 146 | H37: =Trims!L39+Trims!M39 -> 74 | I37: =Trims!N39+Trims!O39 -> 123 | J37: =Trims!P39+Trims!Q39 -> 100 | K37: =Table_Trims[[#This Row],[2025_T3]]+Table_Trims[[#This Row],[2025_T4]] -> 8038
A38: SONASID | B38: SID | C38: Endettement | D38: =Table_Trims[[#This Row],[2022_T2]] -> 1107 | E38: =Table_Trims[[#This Row],[2022_T4]] -> 1240 | F38: =Table_Trims[[#This Row],[2023_T2]] -> 1200 | G38: =Table_Trims[[#This Row],[2023_T4]] -> 1326 | H38: =Table_Trims[[#This Row],[2024_T2]] -> 1188 | I38: =Table_Trims[[#This Row],[2024_T4]] -> 1692 | J38: =Table_Trims[[#This Row],[2025_T2]] -> 1503 | K38: =Table_Trims[[#This Row],[2025_T4]] -> 1854
A39: TGCC S.A | B39: TGC | C39: CA | D39: =Trims!D41+Trims!E41 -> 2249.9 | E39: =Trims!F41+Trims!G41 -> 2811.5 | F39: =Trims!H41+Trims!I41 -> 2912.8 | G39: =Trims!J41+Trims!K41 -> 4191.7 | H39: =Trims!L41+Trims!M41 -> 3786.4 | I39: =Trims!N41+Trims!O41 -> 4260.6 | J39: =Trims!P41+Trims!Q41 -> 4969.1 | K39: =Table_Trims[[#This Row],[2025_T3]]+Table_Trims[[#This Row],[2025_T4]] -> 177
A40: TGCC S.A | B40: TGC | C40: Capex | D40: =Trims!D42+Trims!E42 -> 39.9 | E40: =Trims!F42+Trims!G42 -> 83.7 | F40: =Trims!H42+Trims!I42 -> 167.2 | G40: =Trims!J42+Trims!K42 -> 140.5 | H40: =Trims!L42+Trims!M42 -> 78.3 | I40: =Trims!N42+Trims!O42 -> 94.6 | J40: =Trims!P42+Trims!Q42 -> 206.4 | K40: =Table_Trims[[#This Row],[2025_T3]]+Table_Trims[[#This Row],[2025_T4]] -> -813
...

Sheet Annuel
A1: Colonne1 | B1: Ticker | C1: TypeValeur | D1: 2022 | E1: 2023 | F1: Var %_22-23 | G1: 2024 | H1: Var %_23-24 | I1: 2025 | J1: Var %_24-25
A2: Assurances
A3: ATLANTASANAD | B3: ATL | C3: CA | D3: =Semestriel!D3+Semestriel!E3 -> 5403 | E3: =Semestriel!F3+Semestriel!G3 -> 5112 | F3: =(E3-D3)/D3 -> -0.053858967 | G3: =Semestriel!H3+Semestriel!I3 -> 5260 | H3: =(G3-E3)/E3 -> 0.028951487 | I3: =Table_Semestriel[[#This Row],[S1_2025 ]]+Table_Semestriel[[#This Row],[S2_2025]] -> 6050 | J3: =(Table_Annuel[[#This Row],[2025]]-Table_Annuel[[#This Row],[2024]])/Table_Annuel[[#This Row],[2024]] -> 0.15019011
A4: WAFA ASSURANCE | B4: WAA | C4: CA | D4: =Semestriel!D4+Semestriel!E4 -> 11638 | E4: =Semestriel!F4+Semestriel!G4 -> 12724 | F4: =(E4-D4)/D4 -> 0.093315003 | G4: =Semestriel!H4+Semestriel!I4 -> 13067 | H4: =(G4-E4)/E4 -> 0.026956932 | I4: =Table_Semestriel[[#This Row],[S1_2025 ]]+Table_Semestriel[[#This Row],[S2_2025]] -> 15226 | J4: =(Table_Annuel[[#This Row],[2025]]-Table_Annuel[[#This Row],[2024]])/Table_Annuel[[#This Row],[2024]] -> 0.16522538
A5: Banques
A6: ATTIJARIWAFA BANK | B6: ATW | C6: CA | D6: =Semestriel!D6+Semestriel!E6 -> 26313 | E6: =Semestriel!F6+Semestriel!G6 -> 29943 | F6: =(E6-D6)/D6 -> 0.13795462 | G6: =Semestriel!H6+Semestriel!I6 -> 34507 | H6: =(G6-E6)/E6 -> 0.15242294 | I6: =Semestriel!K6+Semestriel!J6 -> 34921 | J6: =(Table_Annuel[[#This Row],[2025]]-Table_Annuel[[#This Row],[2024]])/Table_Annuel[[#This Row],[2024]] -> 0.011997566
A7: BANK OF AFRICA | B7: BOA | C7: CA | D7: =Semestriel!D7+Semestriel!E7 -> 15626 | E7: =Semestriel!F7+Semestriel!G7 -> 16942 | F7: =(E7-D7)/D7 -> 0.08421861 | G7: =Semestriel!H7+Semestriel!I7 -> 18622 | H7: =(G7-E7)/E7 -> 0.099161846 | I7: =Semestriel!K7+Semestriel!J7 -> 20348 | J7: =(Table_Annuel[[#This Row],[2025]]-Table_Annuel[[#This Row],[2024]])/Table_Annuel[[#This Row],[2024]] -> 0.09268607
A8: BCP | B8: BCP | C8: CA | D8: =Semestriel!D8+Semestriel!E8 -> 20609 | E8: =Semestriel!F8+Semestriel!G8 -> 22795 | F8: =(E8-D8)/D8 -> 0.10607016 | G8: =Semestriel!H8+Semestriel!I8 -> 25601 | H8: =(G8-E8)/E8 -> 0.12309717 | I8: =Semestriel!K8+Semestriel!J8 -> 27000 | J8: =(Table_Annuel[[#This Row],[2025]]-Table_Annuel[[#This Row],[2024]])/Table_Annuel[[#This Row],[2024]] -> 0.054646303
A9: BMCI | B9: BCI | C9: CA | D9: =Semestriel!D9+Semestriel!E9 -> 3055 | E9: =Semestriel!F9+Semestriel!G9 -> 3440 | F9: =(E9-D9)/D9 -> 0.12602291 | G9: =Semestriel!H9+Semestriel!I9 -> 3790 | H9: =(G9-E9)/E9 -> 0.10174419 | I9: =Semestriel!K9+Semestriel!J9 -> 3940 | J9: =(Table_Annuel[[#This Row],[2025]]-Table_Annuel[[#This Row],[2024]])/Table_Annuel[[#This Row],[2024]] -> 0.039577836
A10: CDM | B10: CDM | C10: CA | D10: =Semestriel!D10+Semestriel!E10 -> 2569.1 | E10: =Semestriel!F10+Semestriel!G10 -> 2900 | F10: =(E10-D10)/D10 -> 0.12879997 | G10: =Semestriel!H10+Semestriel!I10 -> 3300 | H10: =(G10-E10)/E10 -> 0.13793103 | I10: =Semestriel!K10+Semestriel!J10 -> 3468 | J10: =(Table_Annuel[[#This Row],[2025]]-Table_Annuel[[#This Row],[2024]])/Table_Annuel[[#This Row],[2024]] -> 0.050909091
A11: CFG BANK | B11: CFG | C11: CA | D11: =Semestriel!D11+Semestriel!E11 -> 500 | E11: =Semestriel!F11+Semestriel!G11 -> 657 | F11: =(E11-D11)/D11 -> 0.314 | G11: =Semestriel!H11+Semestriel!I11 -> 941 | H11: =(G11-E11)/E11 -> 0.43226788 | I11: =Semestriel!K11+Semestriel!J11 -> 1247 | J11: =(Table_Annuel[[#This Row],[2025]]-Table_Annuel[[#This Row],[2024]])/Table_Annuel[[#This Row],[2024]] -> 0.32518597
A12: CIH | B12: CIH | C12: CA | D12: =Semestriel!D12+Semestriel!E12 -> 3518 | E12: =Semestriel!F12+Semestriel!G12 -> 4467.9 | F12: =(E12-D12)/D12 -> 0.27001137 | G12: =Semestriel!H12+Semestriel!I12 -> 4739 | H12: =(G12-E12)/E12 -> 0.060677276 | I12: =+Table_Semestriel[[#This Row],[S1_2025 ]]+Table_Semestriel[[#This Row],[S2_2025]] -> 4441 | J12: =(Table_Annuel[[#This Row],[2025]]-Table_Annuel[[#This Row],[2024]])/Table_Annuel[[#This Row],[2024]] -> -0.062882465
A13: Services Financiers
A14: EQDOM | B14: EQD | C14: CA | D14: =Semestriel!D14+Semestriel!E14 -> 581 | E14: =Semestriel!F14+Semestriel!G14 -> 547 | F14: =(E14/D14)/D14 -> 0.0016204479 | G14: =Semestriel!H14+Semestriel!I14 -> 543 | H14: =(G14-E14)/E14 -> -0.0073126143 | I14: =Table_Semestriel[[#This Row],[S1_2025 ]]+Table_Semestriel[[#This Row],[S2_2025]] -> 2980.8 | J14: =(Table_Annuel[[#This Row],[2025]]-Table_Annuel[[#This Row],[2024]])/Table_Annuel[[#This Row],[2024]] -> 4.4895028
A15: SALAFIN | B15: SLF | C15: CA | D15: =Semestriel!D15+Semestriel!E15 -> 399.293 | E15: =Semestriel!F15+Semestriel!G15 -> 396.459 | F15: =(E15/D15)/D15 -> 0.0024866513 | G15: =Semestriel!H15+Semestriel!I15 -> 378.645 | H15: =(G15-E15)/E15 -> -0.044932767 | I15: =Table_Semestriel[[#This Row],[S1_2025 ]]+Table_Semestriel[[#This Row],[S2_2025]] -> 191 | J15: =(Table_Annuel[[#This Row],[2025]]-Table_Annuel[[#This Row],[2024]])/Table_Annuel[[#This Row],[2024]] -> -0.49556973
A16: Cash Plus | B16: CAP | C16: CA
A17: Agroalimentaire et Boissons
A18: COSUMAR | B18: CSR | C18: CA | D18: =Semestriel!D18+Semestriel!E18 -> 10433 | E18: =Semestriel!F18+Semestriel!G18 -> 10233 | F18: =(E18-D18)/D18 -> -0.019169942 | G18: =Semestriel!H18+Semestriel!I18 -> 10238 | H18: =(G18-E18)/E18 -> 0.00048861526 | I18: =Table_Semestriel[[#This Row],[S1_2025 ]]+Table_Semestriel[[#This Row],[S2_2025]] -> 5584 | J18: =(Table_Annuel[[#This Row],[2025]]-Table_Annuel[[#This Row],[2024]])/Table_Annuel[[#This Row],[2024]] -> -0.45458097
A19: COSUMAR | B19: CSR | C19: Capex | D19: =Semestriel!D19+Semestriel!E19 -> 283 | E19: =Semestriel!F19+Semestriel!G19 -> 242 | F19: =(E19-D19)/D19 -> -0.14487633 | G19: =Semestriel!H19+Semestriel!I19 -> 200 | H19: =(G19-E19)/E19 -> -0.17355372 | I19: =Table_Semestriel[[#This Row],[S1_2025 ]]+Table_Semestriel[[#This Row],[S2_2025]] -> 92 | J19: =(Table_Annuel[[#This Row],[2025]]-Table_Annuel[[#This Row],[2024]])/Table_Annuel[[#This Row],[2024]] -> -0.54
A20: COSUMAR | B20: CSR | C20: Endettement | D20: =Table_Trims[[#This Row],[2022_T4]] -> 2534 | E20: =Table_Trims[[#This Row],[2023_T4]] -> 2575 | F20: =(E20-D20)/D20 -> 0.016179953 | G20: =Table_Trims[[#This Row],[2024_T4]] -> 2489 | H20: =(G20-E20)/E20 -> -0.033398058 | I20: =Table_Semestriel[[#This Row],[S2_2025]] -> 2450 | J20: =(Table_Annuel[[#This Row],[2025]]-Table_Annuel[[#This Row],[2024]])/Table_Annuel[[#This Row],[2024]] -> -0.015668943
A21: LESIEUR CRISTAL | B21: LES | C21: CA | D21: =Semestriel!D21+Semestriel!E21 -> 6889 | E21: =Semestriel!F21+Semestriel!G21 -> 5934 | F21: =(E21-D21)/D21 -> -0.1386268 | G21: =Semestriel!H21+Semestriel!I21 -> 5128 | H21: =(G21-E21)/E21 -> -0.13582744 | I21: =Table_Semestriel[[#This Row],[S1_2025 ]]+Table_Semestriel[[#This Row],[S2_2025]] -> 2977 | J21: =(Table_Annuel[[#This Row],[2025]]-Table_Annuel[[#This Row],[2024]])/Table_Annuel[[#This Row],[2024]] -> -0.41946178
A22: LESIEUR CRISTAL | B22: LES | C22: Capex | D22: =Semestriel!D22+Semestriel!E22 -> 166 | E22: =Semestriel!F22+Semestriel!G22 -> 118 | F22: =(E22-D22)/D22 -> -0.28915663 | G22: =Semestriel!H22+Semestriel!I22 -> 159 | H22: =(G22-E22)/E22 -> 0.34745763 | I22: =Table_Semestriel[[#This Row],[S1_2025 ]]+Table_Semestriel[[#This Row],[S2_2025]] -> 1926 | J22: =(Table_Annuel[[#This Row],[2025]]-Table_Annuel[[#This Row],[2024]])/Table_Annuel[[#This Row],[2024]] -> 11.113208
A23: LESIEUR CRISTAL | B23: LES | C23: Endettement | D23: =Table_Trims[[#This Row],[2022_T4]] -> 1650 | E23: =Table_Trims[[#This Row],[2023_T4]] -> 1385 | F23: =(E23-D23)/D23 -> -0.16060606 | G23: =Table_Trims[[#This Row],[2024_T4]] -> 1381 | H23: =(G23-E23)/E23 -> -0.0028880866 | I23: =Table_Trims[[#This Row],[2025_T4]] -> 1216 | J23: =(Table_Annuel[[#This Row],[2025]]-Table_Annuel[[#This Row],[2024]])/Table_Annuel[[#This Row],[2024]] -> -0.11947864
A24: MUTANDIS | B24: MUT | C24: CA | D24: =Semestriel!D24+Semestriel!E24 -> 2329 | E24: =Semestriel!F24+Semestriel!G24 -> 2497 | F24: =(E24-D24)/D24 -> 0.072133963 | G24: =Semestriel!H24+Semestriel!I24 -> 2116 | H24: =(G24-E24)/E24 -> -0.1525831 | I24: =Table_Semestriel[[#This Row],[S1_2025 ]]+Table_Semestriel[[#This Row],[S2_2025]] -> 944 | J24: =(Table_Annuel[[#This Row],[2025]]-Table_Annuel[[#This Row],[2024]])/Table_Annuel[[#This Row],[2024]] -> -0.55387524
A25: MUTANDIS | B25: MUT | C25: Capex | D25: =Semestriel!D25+Semestriel!E25 -> 218 | E25: =Semestriel!F25+Semestriel!G25 -> 529 | F25: =(E25-D25)/D25 -> 1.4266055 | G25: =Semestriel!H25+Semestriel!I25 -> 261 | H25: =(G25-E25)/E25 -> -0.50661626 | I25: =Table_Semestriel[[#This Row],[S1_2025 ]]+Table_Semestriel[[#This Row],[S2_2025]] -> 318 | J25: =(Table_Annuel[[#This Row],[2025]]-Table_Annuel[[#This Row],[2024]])/Table_Annuel[[#This Row],[2024]] -> 0.2183908
A26: MUTANDIS | B26: MUT | C26: Endettement | D26: =Table_Trims[[#This Row],[2022_T4]] -> 600 | E26: =Table_Trims[[#This Row],[2023_T4]] -> 694 | F26: =(E26-D26)/D26 -> 0.15666667 | G26: =Table_Trims[[#This Row],[2024_T4]] -> 514 | H26: =(G26-E26)/E26 -> -0.25936599 | I26: =Table_Semestriel[[#This Row],[S2_2025]] -> 528 | J26: =(Table_Annuel[[#This Row],[2025]]-Table_Annuel[[#This Row],[2024]])/Table_Annuel[[#This Row],[2024]] -> 0.027237354
A27: SOCIETE DES BOISSONS DU MAROC | B27: SBM | C27: CA | D27: =Semestriel!D27+Semestriel!E27 -> 2913 | E27: =Semestriel!F27+Semestriel!G27 -> 2931 | F27: =(E27-D27)/D27 -> 0.0061791967 | G27: =Semestriel!H27+Semestriel!I27 -> 2861.5 | H27: =(G27-E27)/E27 -> -0.023712044 | I27: =Table_Semestriel[[#This Row],[S1_2025 ]]+Table_Semestriel[[#This Row],[S2_2025]] -> 1206.3 | J27: =(Table_Annuel[[#This Row],[2025]]-Table_Annuel[[#This Row],[2024]])/Table_Annuel[[#This Row],[2024]] -> -0.57843788
A28: SOCIETE DES BOISSONS DU MAROC | B28: SBM | C28: Capex | D28: =Semestriel!D28+Semestriel!E28 -> 68 | E28: =Semestriel!F28+Semestriel!G28 -> 194.7 | F28: =(E28-D28)/D28 -> 1.8632353 | G28: =Semestriel!H28+Semestriel!I28 -> 113.9 | H28: =(G28-E28)/E28 -> -0.41499743 | I28: =Table_Semestriel[[#This Row],[S1_2025 ]]+Table_Semestriel[[#This Row],[S2_2025]] -> 1762.7 | J28: =(Table_Annuel[[#This Row],[2025]]-Table_Annuel[[#This Row],[2024]])/Table_Annuel[[#This Row],[2024]] -> 14.475856
A29: SOCIETE DES BOISSONS DU MAROC | B29: SBM | C29: Endettement | D29: =Table_Trims[[#This Row],[2022_T4]] -> 820 | E29: =Table_Trims[[#This Row],[2023_T4]] -> 745 | F29: =(E29-D29)/D29 -> -0.091463415 | G29: =Table_Trims[[#This Row],[2024_T4]] -> 826 | H29: =(G29-E29)/E29 -> 0.10872483 | I29: =Table_Semestriel[[#This Row],[S2_2025]] -> 930 | J29: =(Table_Annuel[[#This Row],[2025]]-Table_Annuel[[#This Row],[2024]])/Table_Annuel[[#This Row],[2024]] -> 0.12590799
A30: BTP
A31: JET CONTRACTORS | B31: JET | C31: CA | D31: =Semestriel!D31+Semestriel!E31 -> 1713.81 | E31: =Semestriel!F31+Semestriel!G31 -> 2319.71 | F31: =(E31-D31)/D31 -> 0.35353977 | G31: =Semestriel!H31+Semestriel!I31 -> 2673.45 | H31: =(G31-E31)/E31 -> 0.1524932 | I31: =Table_Semestriel[[#This Row],[S1_2025 ]]+Table_Semestriel[[#This Row],[S2_2025]] -> 484.12 | J31: =(Table_Annuel[[#This Row],[2025]]-Table_Annuel[[#This Row],[2024]])/Table_Annuel[[#This Row],[2024]] -> -0.81891563
A32: JET CONTRACTORS | B32: JET | C32: Capex | D32: =Semestriel!D32+Semestriel!E32 -> 67.06 | E32: =Semestriel!F32+Semestriel!G32 -> 35.51 | F32: =(E32-D32)/D32 -> -0.4704742 | G32: =Semestriel!H32+Semestriel!I32 -> 70.89 | H32: =(G32-E32)/E32 -> 0.99633906 | I32: =Table_Semestriel[[#This Row],[S1_2025 ]]+Table_Semestriel[[#This Row],[S2_2025]] -> 37.46 | J32: =(Table_Annuel[[#This Row],[2025]]-Table_Annuel[[#This Row],[2024]])/Table_Annuel[[#This Row],[2024]] -> -0.47157568
A33: JET CONTRACTORS | B33: JET | C33: Endettement | D33: =Table_Trims[[#This Row],[2022_T4]] -> 559 | E33: =Table_Trims[[#This Row],[2023_T4]] -> 902.1 | F33: =(E33-D33)/D33 -> 0.6137746 | G33: =Table_Trims[[#This Row],[2024_T4]] -> 838.24 | H33: =(G33-E33)/E33 -> -0.070790378 | I33: =Table_Semestriel[[#This Row],[S2_2025]] -> 1343 | J33: =(Table_Annuel[[#This Row],[2025]]-Table_Annuel[[#This Row],[2024]])/Table_Annuel[[#This Row],[2024]] -> 0.60216644
A34: LAFARGEHOLCIM MAROC | B34: LHM | C34: CA | D34: =Semestriel!D34+Semestriel!E34 -> 7984 | E34: =Semestriel!F34+Semestriel!G34 -> 8212 | F34: =(E34-D34)/D34 -> 0.028557114 | G34: =Semestriel!H34+Semestriel!I34 -> 8155 | H34: =(G34-E34)/E34 -> -0.0069410619 | I34: =Table_Semestriel[[#This Row],[S1_2025 ]]+Table_Semestriel[[#This Row],[S2_2025]] -> 4532.34 | J34: =(Table_Annuel[[#This Row],[2025]]-Table_Annuel[[#This Row],[2024]])/Table_Annuel[[#This Row],[2024]] -> -0.44422563
A35: LAFARGEHOLCIM MAROC | B35: LHM | C35: Endettement | D35: =Table_Trims[[#This Row],[2022_T4]] -> 843.93 | E35: =Table_Trims[[#This Row],[2023_T4]] -> 1015.9 | F35: =(E35-D35)/D35 -> 0.20377282 | G35: =Table_Trims[[#This Row],[2024_T4]] -> 1001.67 | H35: =(G35-E35)/E35 -> -0.014007284 | I35: =+Table_Semestriel[[#This Row],[S2_2025]] -> 1640 | J35: =(Table_Annuel[[#This Row],[2025]]-Table_Annuel[[#This Row],[2024]])/Table_Annuel[[#This Row],[2024]] -> 0.63726577
A36: SONASID | B36: SID | C36: CA | D36: =Semestriel!D36+Semestriel!E36 -> 4888 | E36: =Semestriel!F36+Semestriel!G36 -> 4995 | F36: =(E36-D36)/D36 -> 0.021890344 | G36: =Semestriel!H36+Semestriel!I36 -> 5494 | H36: =(G36-E36)/E36 -> 0.0998999 | I36: =Table_Semestriel[[#This Row],[S1_2025 ]]+Table_Semestriel[[#This Row],[S2_2025]] -> 7775 | J36: =(Table_Annuel[[#This Row],[2025]]-Table_Annuel[[#This Row],[2024]])/Table_Annuel[[#This Row],[2024]] -> 0.4151802
A37: SONASID | B37: SID | C37: Capex | D37: =Semestriel!D37+Semestriel!E37 -> 142 | E37: =Semestriel!F37+Semestriel!G37 -> 219 | F37: =(E37-D37)/D37 -> 0.54225352 | G37: =Semestriel!H37+Semestriel!I37 -> 197 | H37: =(G37-E37)/E37 -> -0.10045662 | I37: =Table_Semestriel[[#This Row],[S1_2025 ]]+Table_Semestriel[[#This Row],[S2_2025]] -> 8138 | J37: =(Table_Annuel[[#This Row],[2025]]-Table_Annuel[[#This Row],[2024]])/Table_Annuel[[#This Row],[2024]] -> 40.309645
A38: SONASID | B38: SID | C38: Endettement | D38: =Table_Trims[[#This Row],[2022_T4]] -> 1240 | E38: =Table_Trims[[#This Row],[2023_T4]] -> 1326 | F38: =(E38-D38)/D38 -> 0.069354839 | G38: =Table_Trims[[#This Row],[2024_T4]] -> 1692 | H38: =(G38-E38)/E38 -> 0.2760181 | I38: =Table_Semestriel[[#This Row],[S2_2025]] -> 1854 | J38: =(Table_Annuel[[#This Row],[2025]]-Table_Annuel[[#This Row],[2024]])/Table_Annuel[[#This Row],[2024]] -> 0.095744681
A39: TGCC S.A | B39: TGC | C39: CA | D39: =Semestriel!D39+Semestriel!E39 -> 5061.4 | E39: =Semestriel!F39+Semestriel!G39 -> 7104.5 | F39: =(E39-D39)/D39 -> 0.40366302 | G39: =Semestriel!H39+Semestriel!I39 -> 8047 | H39: =(G39-E39)/E39 -> 0.1326624 | I39: =Table_Semestriel[[#This Row],[S1_2025 ]]+Table_Semestriel[[#This Row],[S2_2025]] -> 5146.1 | J39: =(Table_Annuel[[#This Row],[2025]]-Table_Annuel[[#This Row],[2024]])/Table_Annuel[[#This Row],[2024]] -> -0.36049459
A40: TGCC S.A | B40: TGC | C40: Capex | D40: =Semestriel!D40+Semestriel!E40 -> 123.6 | E40: =Semestriel!F40+Semestriel!G40 -> 307.7 | F40: =(E40-D40)/D40 -> 1.4894822 | G40: =Semestriel!H40+Semestriel!I40 -> 172.9 | H40: =(G40-E40)/E40 -> -0.43808905 | I40: =Table_Semestriel[[#This Row],[S1_2025 ]]+Table_Semestriel[[#This Row],[S2_2025]] -> -606.6 | J40: =(Table_Annuel[[#This Row],[2025]]-Table_Annuel[[#This Row],[2024]])/Table_Annuel[[#This Row],[2024]] -> -4.5083864
...

Sheet Base_Finale
A1: Société | B1: Ticker | C1: TypeValeur | D1: Année | E1: Période | F1: Valeur | G1: TypePériode
A2: ATLANTASANAD | B2: ATL | C2: CA | D2: 2022 | E2: T1 | F2: 1960 | G2: Trimestriel
A3: ATLANTASANAD | B3: ATL | C3: CA | D3: 2022 | E3: T2 | F3: 1122 | G3: Trimestriel
A4: ATLANTASANAD | B4: ATL | C4: CA | D4: 2022 | E4: T3 | F4: 1063 | G4: Trimestriel
A5: ATLANTASANAD | B5: ATL | C5: CA | D5: 2022 | E5: T4 | F5: 1258 | G5: Trimestriel
A6: ATLANTASANAD | B6: ATL | C6: CA | D6: 2023 | E6: T1 | F6: 1893 | G6: Trimestriel
A7: ATLANTASANAD | B7: ATL | C7: CA | D7: 2023 | E7: T2 | F7: 1192 | G7: Trimestriel
A8: ATLANTASANAD | B8: ATL | C8: CA | D8: 2023 | E8: T3 | F8: 906 | G8: Trimestriel
A9: ATLANTASANAD | B9: ATL | C9: CA | D9: 2023 | E9: T4 | F9: 1121 | G9: Trimestriel
A10: ATLANTASANAD | B10: ATL | C10: CA | D10: 2024 | E10: T1 | F10: 1962 | G10: Trimestriel
A11: ATLANTASANAD | B11: ATL | C11: CA | D11: 2024 | E11: T2 | F11: 1134 | G11: Trimestriel
A12: ATLANTASANAD | B12: ATL | C12: CA | D12: 2024 | E12: T3 | F12: 855 | G12: Trimestriel
A13: ATLANTASANAD | B13: ATL | C13: CA | D13: 2024 | E13: T4 | F13: 1309 | G13: Trimestriel
... A2658: ARADEI CAPITAL | B2658: ARD | C2658: Endettement | D2658: 2025 | E2658: Annuel | F2658: 4246 | G2658: Annuel

Sheet TCD
A2: TypePériode | B2: Semestriel
A3: TypeValeur | B3: CA
A5: Étiquettes de lignes | B5: Somme de Valeur
A6: AKDITAL | B6: 10307
A7: 2022 | B7: 1034
A8: S1 | B8: 451
A9: S2 | B9: 583
A10: 2023 | B10: 1912
A11: S1 | B11: 823
A12: S2 | B12: 1089
A13: 2024 | B13: 2952
A14: S1 | B14: 1248
A15: S2 | B15: 1704
A16: 2025 | B16: 4409
A17: S1 | B17: 2090
A18: S2 | B18: 2319
A19: Total général | B19: 10307
